Workbook
Name lol: #REF!
Name lol: #REF!
Name lol: #REF!
Name lol: #REF!
Name lol: #REF!
Name lol: #REF!
Name lol: #REF!
Name lol: #REF!
Name lol: #REF!
Name lol: #REF!
Name lol: #REF!

Sheet Monitoring

Sheet setup
A1: Chemin eNET | B1: C:\_eNETDNC
A2: Chemin de DB | B2: C:\Users\Administrator.LT-W7CSMTL-3\Documents\My Data Sources
D3: NE PAS MODIFIER CES INFORMATIONS
A5: Nom des machines | B5: _ST_HORIZONTAL
B6: HCN 1
B7: HCN 2
B8: HCN 3
B9: _ST_SWISS
B10: HARDINGE
B11: SA-32
B12: GANESH
B13: _ST_INTEGREX
B14: INTEGREX 1
B15: INTEGREX 2

Sheet Daily - CNC-01 
G1: Daily report
A2: CNC-01 | E2: Date : | G2: 41428
A6: SHIFT 1 | B6: STATUS | D6: TIME | E6: %
B7: CYCLE ON | D7: =TIME(, ,E7*28800) -> 0.24 | E7: 0.72
B8: CYCLE OFF | D8: =TIME(, ,E8*28800) -> 0.06 | E8: 0.18
B9: SETUP | D9: =TIME(, ,E9*28800) -> 0.026666667 | E9: 0.08
B10: MAINTENANCE | D10: =TIME(, ,E10*28800) -> 0 | E10: 0
B11: TOOLING | D11: =TIME(, ,E11*28800) -> 0 | E11: 0
B12: NO WORK | D12: =TIME(, ,E12*28800) -> 0.0046643519 | E12: 0.014
B13: TRAINING | D13: =TIME(, ,E13*28800) -> 0.0019907407 | E13: 0.006
B14: TOTAL | D14: =TIME(, ,E14*28800) -> 0.33333333 | E14: =SUM(E7:E13) -> 1
A15: =D7+D21+D35 -> 0.73666667 | B15: Other | D15: =SUM(D10:D13) -> 0.0066550926
A16: =17*3600+40*60+48 -> 63648 | B16: CYCLE ON | D16: =D7 -> 0.24
A17: =24*3600 -> 86400 | B17: CYCLE OFF | D17: =D8 -> 0.06
B18: =B9 -> SETUP | D18: =D9 -> 0.026666667
A20: SHIFT 2 | B20: STATUS | D20: TIME | E20: %
B21: CYCLE ON | D21: =TIME(, ,E21*28800) -> 0.21666667 | E21: 0.65
B22: CYCLE OFF | D22: =TIME(, ,E22*28800) -> 0.046666667 | E22: 0.14
B23: SETUP | D23: =TIME(, ,E23*28800) -> 0.03 | E23: 0.09
B24: MAINTENANCE | D24: =TIME(, ,E24*28800) -> 0.013333333 | E24: 0.04
B25: TOOLING | D25: =TIME(, ,E25*28800) -> 0.016666667 | E25: 0.05
B26: NO WORK | D26: =TIME(, ,E26*28800) -> 0.0066666667 | E26: 0.02
B27: TRAINING | D27: =TIME(, ,E27*28800) -> 0.0033333333 | E27: 0.01
B28: TOTAL | D28: =TIME(, ,E28*28800) -> 0.33333333 | E28: =SUM(E21:E27) -> 1
B29: Other | D29: =SUM(D24:D27) -> 0.04
B30: CYCLE ON | D30: =D21 -> 0.21666667
B31: CYCLE OFF | D31: =D22 -> 0.046666667
B32: =B23 -> SETUP | D32: =D23 -> 0.03
A34: SHIFT 3 | B34: STATUS | D34: TIME | E34: %
B35: CYCLE ON | D35: =TIME(, ,E35*28800) -> 0.28 | E35: 0.84
B36: CYCLE OFF | D36: =TIME(, ,E36*28800) -> 0.050393519 | E36: =1-E35-E39 -> 0.1512
B37: SETUP | D37: 0 | E37: 0
B38: MAINTENANCE | D38: =TIME(, ,E38*28800) -> 0 | E38: 0
B39: TOOLING | D39: =TIME(, ,E39*28800) -> 0.0029282407 | E39: 0.0088
B40: NO WORK | D40: =TIME(, ,E40*28800) -> 0 | E40: 0
B41: TRAINING | D41: =TIME(, ,E41*28800) -> 0 | E41: 0
B42: TOTAL | D42: =TIME(, ,E42*28800) -> 0.33333333 | E42: =SUM(E35:E41) -> 1
B43: Other | D43: =SUM(D38:D41) -> 0.0029282407
B44: CYCLE ON | D44: =D35 -> 0.28
B45: CYCLE OFF | D45: =D36 -> 0.050393519
...

Sheet Daily - CNC-02
G1: Daily report
A2: CNC-02 | E2: Date : | G2: 41428
A6: SHIFT 1 | B6: STATUS | D6: TIME | E6: %
B7: CYCLE ON | D7: =TIME(, ,E7*28800) -> 0.13333333 | E7: 0.4
B8: CYCLE OFF | D8: =TIME(, ,E8*28800) -> 0.09 | E8: 0.27
B9: SETUP | D9: =TIME(, ,E9*28800) -> 0.03 | E9: 0.09
B10: MAINTENANCE | D10: =TIME(, ,E10*28800) -> 0.036666667 | E10: 0.11
B11: TOOLING | D11: =TIME(, ,E11*28800) -> 0 | E11: 0
B12: NO WORK | D12: =TIME(, ,E12*28800) -> 0.0033333333 | E12: 0.01
B13: TRAINING | D13: =TIME(, ,E13*28800) -> 0.04 | E13: 0.12
B14: TOTAL | D14: =TIME(, ,E14*28800) -> 0.33333333 | E14: =SUM(E7:E13) -> 1
A15: =D7+D21+D35 -> 0.39666667 | B15: Other | D15: =SUM(D10:D13) -> 0.08
A16: =17*3600+40*60+48 -> 63648 | B16: CYCLE ON | D16: =D7 -> 0.13333333
A17: =24*3600 -> 86400 | B17: CYCLE OFF | D17: =D8 -> 0.09
B18: =B9 -> SETUP | D18: =D9 -> 0.03
A20: SHIFT 2 | B20: STATUS | D20: TIME | E20: %
B21: CYCLE ON | D21: =TIME(, ,E21*28800) -> 0 | E21: 0
B22: CYCLE OFF | D22: =TIME(, ,E22*28800) -> 0.026666667 | E22: 0.08
B23: SETUP | D23: =TIME(, ,E23*28800) -> 0 | E23: 0
B24: MAINTENANCE | D24: =TIME(, ,E24*28800) -> 0.30666667 | E24: 0.92
B25: TOOLING | D25: =TIME(, ,E25*28800) -> 0 | E25: 0
B26: NO WORK | D26: =TIME(, ,E26*28800) -> 0 | E26: 0
B27: TRAINING | D27: =TIME(, ,E27*28800) -> 0 | E27: 0
B28: TOTAL | D28: =TIME(, ,E28*28800) -> 0.33333333 | E28: =SUM(E21:E27) -> 1
B29: Other | D29: =SUM(D24:D27) -> 0.30666667
B30: CYCLE ON | D30: =D21 -> 0
B31: CYCLE OFF | D31: =D22 -> 0.026666667
B32: =B23 -> SETUP | D32: =D23 -> 0
A34: SHIFT 3 | B34: STATUS | D34: TIME | E34: %
B35: CYCLE ON | D35: =TIME(, ,E35*28800) -> 0.26333333 | E35: 0.79
B36: CYCLE OFF | D36: =TIME(, ,E36*28800) -> 0.03 | E36: 0.09
B37: SETUP | D37: =TIME(, ,E37*28800) -> 0.03 | E37: 0.09
B38: MAINTENANCE | D38: =TIME(, ,E38*28800) -> 0 | E38: 0
B39: TOOLING | D39: =TIME(, ,E39*28800) -> 0.01 | E39: 0.03
B40: NO WORK | D40: =TIME(, ,E40*28800) -> 0 | E40: 0
B41: TRAINING | D41: =TIME(, ,E41*28800) -> 0 | E41: 0
B42: TOTAL | D42: =TIME(, ,E42*28800) -> 0.33333333 | E42: =SUM(E35:E41) -> 1
B43: Other | D43: =SUM(D38:D41) -> 0.01
B44: CYCLE ON | D44: =D35 -> 0.26333333
B45: CYCLE OFF | D45: =D36 -> 0.03
...

Sheet Daily - CNC-03
G1: Daily report
A2: CNC-03 | E2: Date : | G2: 41428
A6: SHIFT 1 | B6: STATUS | D6: TIME | E6: %
B7: CYCLE ON | D7: =TIME(, ,E7*28800) -> 0.21333333 | E7: 0.64
B8: CYCLE OFF | D8: =TIME(, ,E8*28800) -> 0.05 | E8: 0.15
B9: SETUP | D9: =TIME(, ,E9*28800) -> 0.046666667 | E9: 0.14
B10: MAINTENANCE | D10: =TIME(, ,E10*28800) -> 0.02 | E10: 0.06
B11: TOOLING | D11: =TIME(, ,E11*28800) -> 0 | E11: 0
B12: NO WORK | D12: =TIME(, ,E12*28800) -> 0.0033333333 | E12: 0.01
B13: TRAINING | D13: =TIME(, ,E13*28800) -> 0 | E13: 0
B14: TOTAL | D14: =TIME(, ,E14*28800) -> 0.33333333 | E14: =SUM(E7:E13) -> 1
A15: =D7+D21+D35 -> 0.66666667 | B15: Other | D15: =SUM(D10:D13) -> 0.023333333
A16: =17*3600+40*60+48 -> 63648 | B16: CYCLE ON | D16: =D7 -> 0.21333333
A17: =24*3600 -> 86400 | B17: CYCLE OFF | D17: =D8 -> 0.05
B18: =B9 -> SETUP | D18: =D9 -> 0.046666667
A20: SHIFT 2 | B20: STATUS | D20: TIME | E20: %
B21: CYCLE ON | D21: =TIME(, ,E21*28800) -> 0.19333333 | E21: 0.58
B22: CYCLE OFF | D22: =TIME(, ,E22*28800) -> 0.066666667 | E22: 0.2
B23: SETUP | D23: =TIME(, ,E23*28800) -> 0.03 | E23: 0.09
B24: MAINTENANCE | D24: =TIME(, ,E24*28800) -> 0 | E24: 0
B25: TOOLING | D25: =TIME(, ,E25*28800) -> 0.043333333 | E25: 0.13
B26: NO WORK | D26: =TIME(, ,E26*28800) -> 0 | E26: 0
B27: TRAINING | D27: =TIME(, ,E27*28800) -> 0 | E27: 0
B28: TOTAL | D28: =TIME(, ,E28*28800) -> 0.33333333 | E28: =SUM(E21:E27) -> 1
B29: Other | D29: =SUM(D24:D27) -> 0.043333333
B30: CYCLE ON | D30: =D21 -> 0.19333333
B31: CYCLE OFF | D31: =D22 -> 0.066666667
B32: =B23 -> SETUP | D32: =D23 -> 0.03
A34: SHIFT 3 | B34: STATUS | D34: TIME | E34: %
B35: CYCLE ON | D35: =TIME(, ,E35*28800) -> 0.26 | E35: 0.78
B36: CYCLE OFF | D36: =TIME(, ,E36*28800) -> 0.031064815 | E36: =1-E35-E39 -> 0.0932
B37: SETUP | D37: 0 | E37: 0
B38: MAINTENANCE | D38: =TIME(, ,E38*28800) -> 0 | E38: 0
B39: TOOLING | D39: =TIME(, ,E39*28800) -> 0.042256944 | E39: 0.1268
B40: NO WORK | D40: =TIME(, ,E40*28800) -> 0 | E40: 0
B41: TRAINING | D41: =TIME(, ,E41*28800) -> 0 | E41: 0
B42: TOTAL | D42: =TIME(, ,E42*28800) -> 0.33333333 | E42: =SUM(E35:E41) -> 1
B43: Other | D43: =SUM(D38:D41) -> 0.042256944
B44: CYCLE ON | D44: =D35 -> 0.26
B45: CYCLE OFF | D45: =D36 -> 0.031064815
...

Sheet Daily - AUTOCLAVE
G1: Daily report
A2: AUTOCLAVE | E2: Date : | G2: 41428
A6: SHIFT 1 | B6: STATUS | D6: TIME | E6: %
B7: CYCLE ON | D7: =TIME(, ,E7*28800) -> 0.25333333 | E7: 0.76
B8: CYCLE OFF | D8: =TIME(, ,E8*28800) -> 0.01 | E8: =1-E7-E9-SUM(E10:E13) -> 0.03
B9: SETUP | D9: =TIME(, ,E9*28800) -> 0.046666667 | E9: 0.14
B10: MAINTENANCE | D10: =TIME(, ,E10*28800) -> 0.02 | E10: 0.06
B11: TOOLING | D11: =TIME(, ,E11*28800) -> 0 | E11: 0
B12: NO WORK | D12: =TIME(, ,E12*28800) -> 0.0033333333 | E12: 0.01
B13: TRAINING | D13: =TIME(, ,E13*28800) -> 0 | E13: 0
B14: TOTAL | D14: =TIME(, ,E14*28800) -> 0.33333333 | E14: =SUM(E7:E13) -> 1
A15: =D7+D21+D35 -> 0.64 | B15: Other | D15: =SUM(D10:D13) -> 0.023333333
A16: =17*3600+40*60+48 -> 63648 | B16: CYCLE ON | D16: =D7 -> 0.25333333
A17: =24*3600 -> 86400 | B17: CYCLE OFF | D17: =D8 -> 0.01
B18: =B9 -> SETUP | D18: =D9 -> 0.046666667
A20: SHIFT 2 | B20: STATUS | D20: TIME | E20: %
B21: CYCLE ON | D21: =TIME(, ,E21*28800) -> 0.33333333 | E21: 1
B22: CYCLE OFF | D22: =TIME(, ,E22*28800) -> 0 | E22: =1-E21-E23-SUM(E24:E27) -> 0
B23: SETUP | D23: =TIME(, ,E23*28800) -> 0 | E23: 0
B24: MAINTENANCE | D24: =TIME(, ,E24*28800) -> 0 | E24: 0
B25: TOOLING | D25: =TIME(, ,E25*28800) -> 0 | E25: 0
B26: NO WORK | D26: =TIME(, ,E26*28800) -> 0 | E26: 0
B27: TRAINING | D27: =TIME(, ,E27*28800) -> 0 | E27: 0
B28: TOTAL | D28: =TIME(, ,E28*28800) -> 0.33333333 | E28: =SUM(E21:E27) -> 1
B29: Other | D29: =SUM(D24:D27) -> 0
B30: CYCLE ON | D30: =D21 -> 0.33333333
B31: CYCLE OFF | D31: =D22 -> 0
B32: =B23 -> SETUP | D32: =D23 -> 0
A34: SHIFT 3 | B34: STATUS | D34: TIME | E34: %
B35: CYCLE ON | D35: =TIME(, ,E35*28800) -> 0.053333333 | E35: 0.16
B36: CYCLE OFF | D36: =TIME(, ,E36*28800) -> 0.04 | E36: =1-E35-E39 -> 0.12
B37: SETUP | D37: 0 | E37: 0
B38: MAINTENANCE | D38: =TIME(, ,E38*28800) -> 0 | E38: 0
B39: TOOLING | D39: =TIME(, ,E39*28800) -> 0.24 | E39: 0.72
B40: NO WORK | D40: =TIME(, ,E40*28800) -> 0 | E40: 0
B41: TRAINING | D41: =TIME(, ,E41*28800) -> 0 | E41: 0
B42: TOTAL | D42: =TIME(, ,E42*28800) -> 0.33333333 | E42: =SUM(E35:E41) -> 1
B43: Other | D43: =SUM(D38:D41) -> 0.24
B44: CYCLE ON | D44: =D35 -> 0.053333333
B45: CYCLE OFF | D45: =D36 -> 0.04
...

Sheet Daily - OVEN 101
G1: Daily report
A2: OVEN 101 | E2: Date : | G2: 41428
A6: SHIFT 1 | B6: STATUS | D6: TIME | E6: %
B7: CYCLE ON | D7: =TIME(, ,E7*28800) -> 0.086666667 | E7: 0.26
B8: CYCLE OFF | D8: =TIME(, ,E8*28800) -> 0.096666667 | E8: =1-E7-E9-SUM(E10:E13) -> 0.29
B9: SETUP | D9: =TIME(, ,E9*28800) -> 0 | E9: 0
B10: MAINTENANCE | D10: =TIME(, ,E10*28800) -> 0 | E10: 0
B11: TOOLING | D11: =TIME(, ,E11*28800) -> 0 | E11: 0
B12: NO WORK | D12: =TIME(, ,E12*28800) -> 0.15 | E12: 0.45
B13: TRAINING | D13: =TIME(, ,E13*28800) -> 0 | E13: 0
B14: TOTAL | D14: =TIME(, ,E14*28800) -> 0.33333333 | E14: =SUM(E7:E13) -> 1
A15: =D7+D21+D35 -> 0.54 | B15: Other | D15: =SUM(D10:D13) -> 0.15
A16: =17*3600+40*60+48 -> 63648 | B16: CYCLE ON | D16: =D7 -> 0.086666667
A17: =24*3600 -> 86400 | B17: CYCLE OFF | D17: =D8 -> 0.096666667
B18: =B9 -> SETUP | D18: =D9 -> 0
A20: SHIFT 2 | B20: STATUS | D20: TIME | E20: %
B21: CYCLE ON | D21: =TIME(, ,E21*28800) -> 0.19333333 | E21: 0.58
B22: CYCLE OFF | D22: =TIME(, ,E22*28800) -> 0.053333333 | E22: =1-E21-E23-SUM(E24:E27) -> 0.16
B23: SETUP | D23: =TIME(, ,E23*28800) -> 0 | E23: 0
B24: MAINTENANCE | D24: =TIME(, ,E24*28800) -> 0 | E24: 0
B25: TOOLING | D25: =TIME(, ,E25*28800) -> 0 | E25: 0
B26: NO WORK | D26: =TIME(, ,E26*28800) -> 0.086666667 | E26: 0.26
B27: TRAINING | D27: =TIME(, ,E27*28800) -> 0 | E27: 0
B28: TOTAL | D28: =TIME(, ,E28*28800) -> 0.33333333 | E28: =SUM(E21:E27) -> 1
B29: Other | D29: =SUM(D24:D27) -> 0.086666667
B30: CYCLE ON | D30: =D21 -> 0.19333333
B31: CYCLE OFF | D31: =D22 -> 0.053333333
B32: =B23 -> SETUP | D32: =D23 -> 0
A34: SHIFT 3 | B34: STATUS | D34: TIME | E34: %
B35: CYCLE ON | D35: =TIME(, ,E35*28800) -> 0.26 | E35: 0.78
B36: CYCLE OFF | D36: =TIME(, ,E36*28800) -> 0.0033333333 | E36: =1-E35-E37-SUM(E38:E41) -> 0.01
B37: SETUP | D37: 0 | E37: 0
B38: MAINTENANCE | D38: =TIME(, ,E38*28800) -> 0 | E38: 0
B39: TOOLING | D39: =TIME(, ,E39*28800) -> 0 | E39: 0
B40: NO WORK | D40: =TIME(, ,E40*28800) -> 0.07 | E40: 0.21
B41: TRAINING | D41: =TIME(, ,E41*28800) -> 0 | E41: 0
B42: TOTAL | D42: =TIME(, ,E42*28800) -> 0.33333333 | E42: =SUM(E35:E41) -> 1
B43: Other | D43: =SUM(D38:D41) -> 0.07
B44: CYCLE ON | D44: =D35 -> 0.26
B45: CYCLE OFF | D45: =D36 -> 0.0033333333
...

Sheet Daily - HCN
A1: Daily report | E1: Date : | G1: 41428
A2: HCN
A5: SHIFT 1 | D5: HOUR | E5: %
B6: CYCLE ON | D6: =TIME(, ,E6*28800) -> 0.3 | E6: 0.9
B7: CYCLE OFF | D7: =TIME(, ,E7*28800) -> 0.016666667 | E7: 0.05
B8: SETUP | D8: =TIME(, ,E8*28800) -> 0.016666667 | E8: 0.05
B9: MAINTENANCE | D9: =TIME(, ,E9*28800) -> 0 | E9: 0
B10: TOOLING | D10: =TIME(, ,E10*28800) -> 0 | E10: 0
B11: NO WORK | D11: =TIME(, ,E11*28800) -> 0 | E11: 0
B12: TRAINING | D12: =TIME(, ,E12*28800) -> 0 | E12: 0
B13: TOTAL | D13: =TIME(, ,28800) -> 0.33333333 | E13: =SUM(E6:E12) -> 1
A14: =D6+D20+D34 -> 0.67541667 | B14: Other | D14: =SUM(D9:D12) -> 0
A15: =16*3600+12*60+36 -> 58356 | B15: CYCLE ON | D15: =D6 -> 0.3
A16: =24*3600 -> 86400 | B16: CYCLE OFF | D16: =D7 -> 0.016666667
B17: =B8 -> SETUP | D17: =D8 -> 0.016666667
A19: SHIFT 2 | D19: HOUR | E19: %
B20: CYCLE ON | D20: =TIME(, ,E20*28800) -> 0.19333333 | E20: 0.58
B21: CYCLE OFF | D21: =TIME(, ,E21*28800) -> 0.066666667 | E21: 0.2
B22: SETUP | D22: =TIME(, ,E22*28800) -> 0.03 | E22: 0.09
B23: MAINTENANCE | D23: =TIME(, ,E23*28800) -> 0 | E23: 0
B24: TOOLING | D24: =TIME(, ,E24*28800) -> 0.043333333 | E24: 0.13
B25: NO WORK | D25: =TIME(, ,E25*28800) -> 0 | E25: 0
B26: TRAINING | D26: =TIME(, ,E26*28800) -> 0 | E26: 0
B27: TOTAL | D27: =TIME(, ,28800) -> 0.33333333 | E27: =SUM(E20:E26) -> 1
B28: Other | D28: =SUM(D23:D26) -> 0.043333333
B29: CYCLE ON | D29: =D20 -> 0.19333333
B30: CYCLE OFF | D30: =D21 -> 0.066666667
B31: =B22 -> SETUP | D31: =D22 -> 0.03
A33: SHIFT 3 | D33: HOUR | E33: %
B34: CYCLE ON | D34: =TIME(, ,E34*22800) -> 0.18208333 | E34: 0.69
B35: CYCLE OFF | D35: =TIME(, ,E35*22800) -> 0.031666667 | E35: 0.12
B36: SETUP | D36: =TIME(, ,E36*22800) -> 0.034305556 | E36: 0.13
B37: MAINTENANCE | D37: =TIME(, ,E37*22800) -> 0 | E37: 0
B38: TOOLING | D38: =TIME(, ,E38*22800) -> 0.015833333 | E38: 0.06
B39: NO WORK | D39: =TIME(, ,E39*22800) -> 0 | E39: 0
B40: TRAINING | D40: =TIME(, ,E40*22800) -> 0 | E40: 0
B41: TOTAL | D41: =TIME(, ,28800) -> 0.33333333 | E41: =SUM(E34:E40) -> 1
B42: Other | D42: =SUM(D37:D40) -> 0.015833333
B43: CYCLE ON | D43: =D34 -> 0.18208333
B44: CYCLE OFF | D44: =D35 -> 0.031666667
...

Sheet Daily - NCT
A1: Daily report | E1: Date : | G1: 41428
A2: NCT
A5: SHIFT 1 | D5: HOUR | E5: %
B6: CYCLE ON | D6: =TIME(, ,E6*28800) -> 0.25333333 | E6: 0.76
B7: CYCLE OFF | D7: =TIME(, ,E7*28800) -> 0.033333333 | E7: 0.1
B8: SETUP | D8: =TIME(, ,E8*28800) -> 0.036666667 | E8: 0.11
B9: MAINTENANCE | D9: =TIME(, ,E9*28800) -> 0 | E9: 0
B10: TOOLING | D10: =TIME(, ,E10*28800) -> 0.01 | E10: 0.03
B11: NO WORK | D11: =TIME(, ,E11*28800) -> 0 | E11: 0
B12: TRAINING | D12: =TIME(, ,E12*28800) -> 0 | E12: 0
B13: TOTAL | D13: =TIME(, ,28800) -> 0.33333333 | E13: =SUM(E6:E12) -> 1
A14: =D6+D20+D34 -> 0.65333333 | B14: Other | D14: =SUM(D9:D12) -> 0.01
A15: =15*3600+40+48 -> 54088 | B15: CYCLE ON | D15: =D6 -> 0.25333333
A16: =24*3600 -> 86400 | B16: CYCLE OFF | D16: =D7 -> 0.033333333
B17: =B8 -> SETUP | D17: =D8 -> 0.036666667
A19: SHIFT 2 | D19: HOUR | E19: %
B20: CYCLE ON | D20: =TIME(, ,E20*28800) -> 0.13333333 | E20: 0.4
B21: CYCLE OFF | D21: =TIME(, ,E21*28800) -> 0.086666667 | E21: 0.26
B22: SETUP | D22: =TIME(, ,E22*28800) -> 0.08 | E22: 0.24
B23: MAINTENANCE | D23: =TIME(, ,E23*28800) -> 0 | E23: 0
B24: TOOLING | D24: =TIME(, ,E24*28800) -> 0.033333333 | E24: 0.1
B25: NO WORK | D25: =TIME(, ,E25*28800) -> 0 | E25: 0
B26: TRAINING | D26: =TIME(, ,E26*28800) -> 0 | E26: 0
B27: TOTAL | D27: =TIME(, ,28800) -> 0.33333333 | E27: =SUM(E20:E26) -> 1
B28: Other | D28: =SUM(D23:D26) -> 0.033333333
B29: CYCLE ON | D29: =D20 -> 0.13333333
B30: CYCLE OFF | D30: =D21 -> 0.086666667
B31: =B22 -> SETUP | D31: =D22 -> 0.08
A33: SHIFT 3 | D33: HOUR | E33: %
B34: CYCLE ON | D34: =TIME(, ,E34*28800) -> 0.26666667 | E34: 0.8
B35: CYCLE OFF | D35: =TIME(, ,E35*28800) -> 0.026666667 | E35: 0.08
B36: SETUP | D36: =TIME(, ,E36*28800) -> 0.023333333 | E36: 0.07
B37: MAINTENANCE | D37: =TIME(, ,E37*28800) -> 0 | E37: 0
B38: TOOLING | D38: =TIME(, ,E38*28800) -> 0.016666667 | E38: 0.05
B39: NO WORK | D39: =TIME(, ,E39*28800) -> 0 | E39: 0
B40: TRAINING | D40: =TIME(, ,E40*28800) -> 0 | E40: 0
B41: TOTAL | D41: =TIME(, ,28800) -> 0.33333333 | E41: =SUM(E34:E40) -> 1
B42: Other | D42: =SUM(D37:D40) -> 0.016666667
B43: CYCLE ON | D43: =D34 -> 0.26666667
B44: CYCLE OFF | D44: =D35 -> 0.026666667
...

Sheet Daily - All
P1: Daily report
J2: DEP. AS203 | N2: Date : | P2: 41428
B5: CNC-01 | D5: HOUR | F5: CNC-02 | H5: HOUR
B6: CYCLE ON | D6: =SUM('Daily - CNC-01 '!D7+'Daily - CNC-01 '!D21+'Daily - CNC-01 '!D35)/3 -> 0.24555556 | F6: CYCLE ON | H6: =SUM('Daily - CNC-02'!E7,'Daily - CNC-02'!E21,'Daily - CNC-02'!E35)/3 -> 0.39666667
B7: CYCLE OFF | D7: =SUM('Daily - CNC-01 '!D8+'Daily - CNC-01 '!D22+'Daily - CNC-01 '!D36)/3 -> 0.052353395 | F7: CYCLE OFF | H7: =SUM('Daily - CNC-02'!E8,'Daily - CNC-02'!E22,'Daily - CNC-02'!E36)/3 -> 0.14666667
B8: SETUP | D8: =SUM('Daily - CNC-01 '!D9+'Daily - CNC-01 '!D23+'Daily - CNC-01 '!D37)/3 -> 0.018888889 | F8: SETUP | H8: =SUM('Daily - CNC-02'!E9,'Daily - CNC-02'!E23,'Daily - CNC-02'!E37)/3 -> 0.06
B9: MAINTENANCE | D9: =SUM('Daily - CNC-01 '!D10+'Daily - CNC-01 '!D24+'Daily - CNC-01 '!D38) -> 0.013333333 | F9: MAINTENANCE | H9: =SUM('Daily - CNC-02'!E10,'Daily - CNC-02'!E24,'Daily - CNC-02'!E38) -> 1.03
B10: TOOLING | D10: =SUM('Daily - CNC-01 '!D11+'Daily - CNC-01 '!D25+'Daily - CNC-01 '!D39) -> 0.019594907 | F10: TOOLING | H10: =SUM('Daily - CNC-02'!E11,'Daily - CNC-02'!E25,'Daily - CNC-02'!E39) -> 0.03
B11: NO WORK | D11: =SUM('Daily - CNC-01 '!D12+'Daily - CNC-01 '!D26+'Daily - CNC-01 '!D40) -> 0.011331019 | F11: NO WORK | H11: =SUM('Daily - CNC-02'!E12,'Daily - CNC-02'!E26,'Daily - CNC-02'!E40) -> 0.01
B12: TRAINING | D12: =SUM('Daily - CNC-01 '!D13+'Daily - CNC-01 '!D27+'Daily - CNC-01 '!D41) -> 0.0053240741 | F12: TRAINING | H12: =SUM('Daily - CNC-02'!E13,'Daily - CNC-02'!E27,'Daily - CNC-02'!E41) -> 0.12
B13: TOTAL | D13: =SUM(D6:D12) -> 0.36638117 | F13: TOTAL | H13: =SUM(H6:H12) -> 1.7933333
B14: Other | D14: =SUM(D9:D12)/3 -> 0.016527778 | F14: Other | H14: =SUM(H9:H12)/3 -> 0.39666667
B15: CYCLE ON | D15: =D6 -> 0.24555556 | F15: CYCLE ON | H15: =H6 -> 0.39666667
B16: CYCLE OFF | D16: =D7 -> 0.052353395 | F16: CYCLE OFF | H16: =H7 -> 0.14666667
B17: SETUP | D17: =D8 -> 0.018888889 | F17: SETUP | H17: =H8 -> 0.06
B19: CNC-03 | F19: Autoclave
B20: CYCLE ON | D20: =SUM('Daily - CNC-03'!E7,'Daily - CNC-03'!E21,'Daily - CNC-03'!E35)/3 -> 0.66666667 | F20: CYCLE ON | H20: =SUM('Daily - AUTOCLAVE'!E7,'Daily - AUTOCLAVE'!E21,'Daily - AUTOCLAVE'!E35)/3 -> 0.64
B21: CYCLE OFF | D21: =SUM('Daily - CNC-03'!E8,'Daily - CNC-03'!E22,'Daily - CNC-03'!E36)/3 -> 0.14773333 | F21: CYCLE OFF | H21: =SUM('Daily - AUTOCLAVE'!E8,'Daily - AUTOCLAVE'!E22,'Daily - AUTOCLAVE'!E36)/3 -> 0.05
B22: SETUP | D22: =SUM('Daily - CNC-03'!E9,'Daily - CNC-03'!E23,'Daily - CNC-03'!E37)/3 -> 0.076666667 | F22: SETUP | H22: =SUM('Daily - AUTOCLAVE'!E9,'Daily - AUTOCLAVE'!E23,'Daily - AUTOCLAVE'!E37)/3 -> 0.046666667
B23: MAINTENANCE | D23: =SUM('Daily - CNC-03'!E10,'Daily - CNC-03'!E24,'Daily - CNC-03'!E38)/3 -> 0.02 | F23: MAINTENANCE | H23: =SUM('Daily - AUTOCLAVE'!E10,'Daily - AUTOCLAVE'!E24,'Daily - AUTOCLAVE'!E38) -> 0.06
B24: TOOLING | D24: =SUM('Daily - CNC-03'!E11,'Daily - CNC-03'!E25,'Daily - CNC-03'!E39)/3 -> 0.0856 | F24: TOOLING | H24: =SUM('Daily - AUTOCLAVE'!E11,'Daily - AUTOCLAVE'!E25,'Daily - AUTOCLAVE'!E39) -> 0.72
B25: NO WORK | D25: =SUM('Daily - CNC-03'!E12,'Daily - CNC-03'!E26,'Daily - CNC-03'!E40)/3 -> 0.0033333333 | F25: NO WORK | H25: =SUM('Daily - AUTOCLAVE'!E12,'Daily - AUTOCLAVE'!E26,'Daily - AUTOCLAVE'!E40) -> 0.01
B26: TRAINING | D26: =SUM('Daily - CNC-03'!E13,'Daily - CNC-03'!E27,'Daily - CNC-03'!E41)/3 -> 0 | F26: TRAINING | H26: =SUM('Daily - AUTOCLAVE'!E13,'Daily - AUTOCLAVE'!E27,'Daily - AUTOCLAVE'!E41) -> 0
B27: TOTAL | D27: =SUM(D20:D26) -> 1 | F27: TOTAL | H27: =SUM(H20:H26) -> 1.5266667
B28: Other | D28: =SUM(D23:D26) -> 0.10893333 | F28: Other | H28: =SUM(H23:H26)/3 -> 0.26333333
B29: CYCLE ON | D29: =D20 -> 0.66666667 | F29: CYCLE ON | H29: =H20 -> 0.64
B30: CYCLE OFF | D30: =D21 -> 0.14773333 | F30: CYCLE OFF | H30: =H21 -> 0.05
B31: SETUP | D31: =D22 -> 0.076666667 | F31: SETUP | H31: =H22 -> 0.046666667
B33: Oven-101 | P33: Cycle On
B34: CYCLE ON | D34: =SUM('Daily - OVEN 101'!E7,'Daily - OVEN 101'!E21,'Daily - OVEN 101'!E35)/3 -> 0.54 | F34: CYCLE ON | H34: =SUM('Daily - NCT'!D6,'Daily - NCT'!D20,'Daily - NCT'!D34) -> 0.65333333
B35: CYCLE OFF | D35: =SUM('Daily - OVEN 101'!E8,'Daily - OVEN 101'!E22,'Daily - OVEN 101'!E36)/3 -> 0.15333333 | F35: CYCLE OFF | H35: =SUM('Daily - NCT'!D7,'Daily - NCT'!D21,'Daily - NCT'!D35) -> 0.14666667 | P35: Cycle Off
B36: SETUP | D36: =SUM('Daily - OVEN 101'!E9,'Daily - OVEN 101'!E23,'Daily - OVEN 101'!E37)/3 -> 0 | F36: SETUP | H36: =SUM('Daily - NCT'!D8,'Daily - NCT'!D22,'Daily - NCT'!D36) -> 0.14
B37: MAINTENANCE | D37: =SUM('Daily - OVEN 101'!E10,'Daily - OVEN 101'!E24,'Daily - OVEN 101'!E38)/3 -> 0 | F37: MAINTENANCE | H37: =SUM('Daily - NCT'!D9,'Daily - NCT'!D23,'Daily - NCT'!D37) -> 0 | P37: Setup
B38: TOOLING | D38: =SUM('Daily - OVEN 101'!E11,'Daily - OVEN 101'!E25,'Daily - OVEN 101'!E39)/3 -> 0 | F38: TOOLING | H38: =SUM('Daily - NCT'!D10,'Daily - NCT'!D24,'Daily - NCT'!D38) -> 0.06
B39: NO WORK | D39: =SUM('Daily - OVEN 101'!E12,'Daily - OVEN 101'!E26,'Daily - OVEN 101'!E40)/3 -> 0.30666667 | F39: NO WORK | H39: =SUM('Daily - NCT'!D11,'Daily - NCT'!D25,'Daily - NCT'!D39) -> 0 | P39: Other
B40: TRAINING | D40: =SUM('Daily - OVEN 101'!E13,'Daily - OVEN 101'!E27,'Daily - OVEN 101'!E41)/3 -> 0 | F40: TRAINING | H40: =SUM('Daily - NCT'!D12,'Daily - NCT'!D26,'Daily - NCT'!D40) -> 0
B41: TOTAL | D41: =SUM(D34:D40) -> 1
B42: Other | D42: =SUM(D37:D40)/3 -> 0.10222222 | F42: Other | H42: =SUM(H37:H40) -> 0.06
B43: CYCLE ON | D43: =D34 -> 0.54 | F43: CYCLE ON | H43: =H34 -> 0.65333333
B44: CYCLE OFF | D44: =D35 -> 0.15333333 | F44: CYCLE OFF | H44: =H35 -> 0.14666667
...

Sheet Asset 1 Trend
A2: Utilization Trend | D2: Period
A3: CNC - 01 | E3: 41277 | F3: - | G3: 41428
A5: Utilization Trend - Shift 1:
A18: Utilization Trend - Shift 2:
A31: Utilization Trend - Shift 3:

Sheet Trend - Mazat 1
A1: Mazat 1
C2: =TREND(C4:C155) -> 0.39185407 | E2: =TREND(E4:E155) -> 0.36850522 | H2: =TREND(H4:H155) -> 0.46754871
A3: Date | C3: Shift 1 | E3: Shift 2 | H3: Shift 3
A4: 41277 | B4: =B6-0.1 -> 0.181 | C4: =RAND()*0.08+B4-0.02 -> 0.1615336 | D4: =D5-0.005 -> 0.3501 | E4: =RAND()*0.2+D4-0.2 -> 0.19684053 | G4: 0.23 | H4: =RAND()*0.2+G4-0.2 -> 0.17881587
A5: =A4+1 -> 41278 | B5: =B7-0.1 -> 0.431 | C5: =RAND()*0.08+B5-0.02 -> 0.4630006 | D5: =D6-0.005 -> 0.3551 | E5: =RAND()*0.2+D5-0.2 -> 0.27508304 | G5: 0.22 | H5: =RAND()*0.2+G5-0.2 -> 0.084515328
A6: =A5+1 -> 41279 | B6: =B8-0.1 -> 0.281 | C6: =RAND()*0.08+B6-0.02 -> 0.30439525 | D6: =D7-0.005 -> 0.3601 | E6: =RAND()*0.2+D6-0.2 -> 0.2585581 | G6: 0.24 | H6: =RAND()*0.2+G6-0.2 -> 0.079414738
A7: =A6+1 -> 41280 | B7: =B9-0.1 -> 0.531 | C7: =RAND()*0.08+B7-0.02 -> 0.53376347 | D7: =D8-0.005 -> 0.3651 | E7: =RAND()*0.2+D7-0.2 -> 0.19633233 | G7: 0.32 | H7: =RAND()*0.2+G7-0.2 -> 0.30668405
A8: =A7+1 -> 41281 | B8: =B10-0.1 -> 0.381 | C8: =RAND()*0.08+B8-0.02 -> 0.42873726 | D8: =D9-0.005 -> 0.3701 | E8: =RAND()*0.2+D8-0.2 -> 0.24466859 | G8: 0.25 | H8: =RAND()*0.2+G8-0.2 -> 0.16261738
A9: =A8+1 -> 41282 | B9: =B10+0.15 -> 0.631 | C9: =RAND()*0.08+B9-0.02 -> 0.6678836 | D9: =D10-0.005 -> 0.3751 | E9: =RAND()*0.2+D9-0.2 -> 0.2355196 | G9: =G10-0.036 -> 0.2182 | H9: =RAND()*0.2+G9-0.2 -> 0.21264811
A10: =A9+1 -> 41283 | B10: =B11+0.15 -> 0.481 | C10: =RAND()*0.08+B10-0.02 -> 0.48934421 | D10: =D11-0.005 -> 0.3801 | E10: =RAND()*0.2+D10-0.2 -> 0.289118 | G10: =G11-0.036 -> 0.2542 | H10: =RAND()*0.2+G10-0.2 -> 0.086089345
A11: =A10+1 -> 41284 | B11: =B12-0.01 -> 0.331 | C11: =RAND()*0.08+B11-0.02 -> 0.35087425 | D11: =D12-0.005 -> 0.3851 | E11: =RAND()*0.2+D11-0.2 -> 0.27145304 | G11: =G12-0.036 -> 0.2902 | H11: =RAND()*0.2+G11-0.2 -> 0.17447452
A12: =A11+1 -> 41285 | B12: =B13-0.01 -> 0.341 | C12: =RAND()*0.08+B12-0.02 -> 0.32783701 | D12: =D13-0.005 -> 0.3901 | E12: =RAND()*0.2+D12-0.2 -> 0.33169607 | G12: =G13-0.036 -> 0.3262 | H12: =RAND()*0.2+G12-0.2 -> 0.30101619
A13: =A12+1 -> 41286 | B13: =B14-0.01 -> 0.351 | C13: =RAND()*0.08+B13-0.02 -> 0.33198903 | D13: =D14-0.005 -> 0.3951 | E13: =RAND()*0.2+D13-0.2 -> 0.26985305 | G13: =G14-0.036 -> 0.3622 | H13: =RAND()*0.2+G13-0.2 -> 0.30889511
A14: =A13+1 -> 41287 | B14: =B15-0.01 -> 0.361 | C14: =RAND()*0.08+B14-0.02 -> 0.3976328 | D14: =D15-0.005 -> 0.4001 | E14: =RAND()*0.2+D14-0.2 -> 0.37396304 | G14: =G15-0.036 -> 0.3982 | H14: =RAND()*0.2+G14-0.2 -> 0.27980903
A15: =A14+1 -> 41288 | B15: =B16-0.01 -> 0.371 | C15: =RAND()*0.08+B15-0.02 -> 0.35410125 | D15: =D16-0.005 -> 0.4051 | E15: =RAND()*0.2+D15-0.2 -> 0.2146306 | G15: =G16-0.036 -> 0.4342 | H15: =RAND()*0.2+G15-0.2 -> 0.40281812
A16: =A15+1 -> 41289 | B16: =B17-0.01 -> 0.381 | C16: =RAND()*0.08+B16-0.02 -> 0.37717418 | D16: =D17-0.005 -> 0.4101 | E16: =RAND()*0.2+D16-0.2 -> 0.29755283 | G16: =G17-0.036 -> 0.4702 | H16: =RAND()*0.2+G16-0.2 -> 0.4681251
A17: =A16+1 -> 41290 | B17: =B18-0.01 -> 0.391 | C17: =RAND()*0.08+B17-0.02 -> 0.38248217 | D17: =D18-0.005 -> 0.4151 | E17: =RAND()*0.2+D17-0.2 -> 0.24675677 | G17: =G18-0.036 -> 0.5062 | H17: =RAND()*0.2+G17-0.2 -> 0.41140998
A18: =A17+1 -> 41291 | B18: =B19-0.002 -> 0.401 | C18: =RAND()*0.08+B18-0.02 -> 0.42091076 | D18: =D19-0.005 -> 0.4201 | E18: =RAND()*0.2+D18-0.2 -> 0.37003954 | G18: =G19-0.036 -> 0.5422 | H18: =RAND()*0.2+G18-0.2 -> 0.52400293
A19: =A18+1 -> 41292 | B19: =B20-0.002 -> 0.403 | C19: =RAND()*0.08+B19-0.02 -> 0.39818185 | D19: =D20-0.005 -> 0.4251 | E19: =RAND()*0.2+D19-0.2 -> 0.27362203 | G19: =G20-0.036 -> 0.5782 | H19: =RAND()*0.2+G19-0.2 -> 0.47451954
A20: =A19+1 -> 41293 | B20: =B21-0.002 -> 0.405 | C20: =RAND()*0.08+B20-0.02 -> 0.43279428 | D20: =D21-0.005 -> 0.4301 | E20: =RAND()*0.2+D20-0.2 -> 0.31277734 | G20: =G21-0.036 -> 0.6142 | H20: =RAND()*0.2+G20-0.2 -> 0.49142318
A21: =A20+1 -> 41294 | B21: =B22-0.002 -> 0.407 | C21: =RAND()*0.08+B21-0.02 -> 0.39837416 | D21: =D22-0.005 -> 0.4351 | E21: =RAND()*0.2+D21-0.2 -> 0.35665399 | G21: =G22-0.036 -> 0.6502 | H21: =RAND()*0.2+G21-0.2 -> 0.56800611
A22: =A21+1 -> 41295 | B22: =B23-0.002 -> 0.409 | C22: =RAND()*0.08+B22-0.02 -> 0.39626695 | D22: =D23-0.005 -> 0.4401 | E22: =RAND()*0.2+D22-0.2 -> 0.36360748 | G22: =G23-0.036 -> 0.6862 | H22: =RAND()*0.2+G22-0.2 -> 0.64857834
A23: =A22+1 -> 41296 | B23: =B24-0.002 -> 0.411 | C23: =RAND()*0.08+B23-0.02 -> 0.45301258 | D23: =D24-0.005 -> 0.4451 | E23: =RAND()*0.2+D23-0.2 -> 0.31884585 | G23: =G24-0.036 -> 0.7222 | H23: =0.58 -> 0.58
A24: =A23+1 -> 41297 | B24: =B25-0.002 -> 0.413 | C24: =RAND()*0.08+B24-0.02 -> 0.42390722 | D24: =D25-0.005 -> 0.4501 | E24: =RAND()*0.2+D24-0.2 -> 0.38995657 | G24: =G25+0.025 -> 0.7582 | H24: =RAND()*0.2+G24-0.2 -> 0.7361383
A25: =A24+1 -> 41298 | B25: =B26-0.002 -> 0.415 | C25: =RAND()*0.08+B25-0.02 -> 0.42101022 | D25: =D26-0.005 -> 0.4551 | E25: =RAND()*0.2+D25-0.2 -> 0.40247588 | G25: =G26+0.025 -> 0.7332 | H25: =0.62 -> 0.62
A26: =A25+1 -> 41299 | B26: =B27-0.002 -> 0.417 | C26: =RAND()*0.08+B26-0.02 -> 0.46988167 | D26: =D27-0.005 -> 0.4601 | E26: =RAND()*0.2+D26-0.2 -> 0.36394417 | G26: =G27+0.025 -> 0.7082 | H26: =RAND()*0.2+G26-0.2 -> 0.64784134
A27: =A26+1 -> 41300 | B27: =B28-0.002 -> 0.419 | C27: =RAND()*0.08+B27-0.02 -> 0.40669917 | D27: =D28-0.005 -> 0.4651 | E27: =RAND()*0.2+D27-0.2 -> 0.3977891 | G27: =G28+0.025 -> 0.6832 | H27: =RAND()*0.2+G27-0.2 -> 0.55859386
A28: =A27+1 -> 41301 | B28: =B29-0.002 -> 0.421 | C28: =RAND()*0.08+B28-0.02 -> 0.44156003 | D28: =D29-0.005 -> 0.4701 | E28: =RAND()*0.2+D28-0.2 -> 0.30216289 | G28: =G29+0.025 -> 0.6582 | H28: =RAND()*0.2+G28-0.2 -> 0.63840914
A29: =A28+1 -> 41302 | B29: =B30-0.002 -> 0.423 | C29: =RAND()*0.08+B29-0.02 -> 0.40941362 | D29: =D30-0.005 -> 0.4751 | E29: =RAND()*0.2+D29-0.2 -> 0.37397431 | G29: =G30+0.025 -> 0.6332 | H29: =RAND()*0.2+G29-0.2 -> 0.51066013
A30: =A29+1 -> 41303 | B30: =B31-0.002 -> 0.425 | C30: =RAND()*0.08+B30-0.02 -> 0.46515939 | D30: =D31-0.005 -> 0.4801 | E30: =RAND()*0.2+D30-0.2 -> 0.4635888 | G30: =G31+0.025 -> 0.6082 | H30: =RAND()*0.2+G30-0.2 -> 0.55803607
A31: =A30+1 -> 41304 | B31: =B32-0.002 -> 0.427 | C31: =RAND()*0.08+B31-0.02 -> 0.42659367 | D31: =D32-0.005 -> 0.4851 | E31: =RAND()*0.2+D31-0.2 -> 0.40607174 | G31: =G32+0.025 -> 0.5832 | H31: =RAND()*0.2+G31-0.2 -> 0.50700903
A32: =A31+1 -> 41305 | B32: =B33-0.002 -> 0.429 | C32: =RAND()*0.08+B32-0.02 -> 0.47780839 | D32: =D33-0.005 -> 0.4901 | E32: =RAND()*0.2+D32-0.2 -> 0.48346586 | G32: =G33+0.025 -> 0.5582 | H32: =RAND()*0.2+G32-0.2 -> 0.52682518
A33: =A32+1 -> 41306 | B33: =B34-0.002 -> 0.431 | C33: =RAND()*0.08+B33-0.02 -> 0.44615927 | D33: =D34-0.005 -> 0.4951 | E33: =RAND()*0.2+D33-0.2 -> 0.32646967 | G33: =G34+0.025 -> 0.5332 | H33: =RAND()*0.2+G33-0.2 -> 0.4791505
A34: =A33+1 -> 41307 | B34: =B35-0.002 -> 0.433 | C34: =RAND()*0.08+B34-0.02 -> 0.43197368 | D34: =D35-0.005 -> 0.5001 | E34: =RAND()*0.2+D34-0.2 -> 0.42899519 | G34: =G35+0.025 -> 0.5082 | H34: =RAND()*0.2+G34-0.2 -> 0.34734596
A35: =A34+1 -> 41308 | B35: =B36-0.002 -> 0.435 | C35: =RAND()*0.08+B35-0.02 -> 0.47972424 | D35: =D36-0.005 -> 0.5051 | E35: =RAND()*0.2+D35-0.2 -> 0.47176112 | G35: =G36+0.025 -> 0.4832 | H35: =RAND()*0.2+G35-0.2 -> 0.4813446
A36: =A35+1 -> 41309 | B36: =B37-0.002 -> 0.437 | C36: =RAND()*0.08+B36-0.02 -> 0.44792248 | D36: =D37-0.005 -> 0.5101 | E36: =RAND()*0.2+D36-0.2 -> 0.37196717 | G36: =G37+0.025 -> 0.4582 | H36: =RAND()*0.2+G36-0.2 -> 0.39467143
A37: =A36+1 -> 41310 | B37: =B38-0.002 -> 0.439 | C37: =RAND()*0.1+B37-0.1 -> 0.38379897 | D37: =D38-0.005 -> 0.5151 | E37: =RAND()*0.2+D37-0.2 -> 0.34265023 | G37: =G38-0.058 -> 0.4332 | H37: =RAND()*0.2+G37-0.2 -> 0.36957856
A38: =A37+1 -> 41311 | B38: =B39-0.002 -> 0.441 | C38: =RAND()*0.1+B38-0.02 -> 0.42425723 | D38: =D39-0.0045 -> 0.5201 | E38: =RAND()*0.2+D38-0.2 -> 0.32384737 | G38: =G39-0.058 -> 0.4912 | H38: =RAND()*0.2+G38-0.2 -> 0.42130723
A39: =A38+1 -> 41312 | B39: =B40-0.002 -> 0.443 | C39: =RAND()*0.1+B39-0.02 -> 0.4506165 | D39: =D40-0.0045 -> 0.5246 | E39: =RAND()*0.2+D39-0.2 -> 0.48810554 | G39: =G40-0.058 -> 0.5492 | H39: =RAND()*0.2+G39-0.2 -> 0.40525351
A40: =A39+1 -> 41313 | B40: =B41-0.002 -> 0.445 | C40: =RAND()*0.1+B40-0.02 -> 0.4999881 | D40: =D41-0.0045 -> 0.5291 | E40: =RAND()*0.2+D40-0.2 -> 0.33643215 | G40: =G41-0.058 -> 0.6072 | H40: =RAND()*0.2+G40-0.2 -> 0.55436692
...

Sheet Efficiency
A2: Utilization Trend | I2: Date
A3: All Machines | G3: 41428
A7: Machine | C7: Availbility | E7: Performance | G7: Quality | I7: OEE
A9: CNC-01 | C9: ='Daily - CNC-01 '!A16/'Daily - CNC-01 '!A17 -> 0.73666667 | E9: 0.89 | G9: 0.93 | H9: 1 | I9: =G9*E9*C9 -> 0.609739
A10: CNC-02 | C10: ='Daily - CNC-02'!A16/'Daily - CNC-02'!A17 -> 0.73666667 | E10: 0.83 | G10: 0.74 | I10: =G10*E10*C10 -> 0.45246067
A11: CNC-03 | C11: ='Daily - CNC-03'!A16/'Daily - CNC-03'!A17 -> 0.73666667 | E11: 0.74 | G11: 0.68 | I11: =G11*E11*C11 -> 0.37069067
A12: AUTOCL. | C12: ='Daily - HCN'!A15/'Daily - HCN'!A16 -> 0.67541667 | E12: 0.91 | G12: 0.73 | I12: =G12*E12*C12 -> 0.44867929
A13: OVEN-101 | C13: ='Daily - NCT'!A15/'Daily - NCT'!A16 -> 0.62601852 | E13: 0.97 | G13: 0.88 | I13: =G13*E13*C13 -> 0.53436941

Sheet Efficiency - ASSET 1 - Shift 1
A1: Utilization Trend | E1: Date : | J1: 41427
A2: CNC-01 | B2: Shift 1
A4: Shift 1:
A5: Machine | C5: Availbility | E5: OEE | G5: Evolution (1 month) | J5: Evolution (6 month)
A7: Shift Duration | C7: 480
A8: Operation Time | C8: 297
A9: Availability | C9: 0.625
A10: Units Produced | C10: 463
A11: Good units | C11: 430
A12: Quality | C12: 0.93
A13: Rate | C13: 1.44
A14: Performance | C14: 0.89
E15: 0.5173 | G15: -0.02 | J15: ="+34%" -> +34%
A17: Shift 2:
A18: Machine | C18: Availbility | E18: OEE | G18: Evolution (1 month) | J18: Evolution (6 month)
A20: Shift Duration | C20: 480
A21: Operation Time | C21: 282
A22: Availability | C22: 0.5875
A23: Units Produced | C23: 442
A24: Good units | C24: 408
A25: Quality | C25: 0.923
A26: Rate | C26: 1.44
A27: Performance | C27: 0.89
E28: 0.4749 | G28: -0.04 | J28: ="+12%" -> +12%
A30: Shift 3:
A31: Machine | C31: Availbility | E31: OEE | G31: Evolution (1 month) | J31: Evolution (6 month)
A33: Shift Duration | C33: 480
A34: Operation Time | C34: 358
A35: Availability | C35: 0.7458
A36: Units Produced | C36: 473
A37: Good units | C37: 468
A38: Quality | C38: 0.9894
A39: Rate | C39: 1.3
A40: Performance | C40: 0.77
E41: 0.5584 | G41: 0.08 | J41: ="+34%" -> +34%

Sheet Sheet1
